Workbook

Sheet Read Me (Nidhi)
B1: NIKHIL — AI PRODUCT ENGINEER | SPRINT PLAN
B2: Sprint Master: Nidhi • Start: 20 June 2026 • Pace: ~8 hrs/day × 6 days (Sun off) • 2-week sprints
B4: HOW TO USE THIS TRACKER
B5: 1. 'Sprint Board' = the live to-do board (Jira-style). Every task is one row.
B6: 2. Update the STATUS column only — pick from dropdown: To Do / In Progress / Done / Blocked. Colour changes automatically.
B7: 3. 'Dashboard' auto-calculates % done per sprint + overall. Nothing to fill there — it reads the board live.
B8: 4. 'Sprint Plan' = the big-picture map: each sprint's theme + the demo/deliverable that must exist at sprint-end.
B9: 5. 'Phase 2 Backlog' = growth items for AFTER the job / better-company push. No dates — pulled in later.
B11: THE ONE TRIGGER THAT MATTERS
B12: 🚩 Applications START when M1 (Invoice Intelligence) is demo-able — slick UI + an eval dashboard proving accuracy.
B13: That lands at the start of Sprint 4 (~early Aug). M1 = the whole job-getting engine. M2/M3 are interview talking-points built WHILE applying.
B15: PRIORITY LEGEND
... B20: STATUS COLOURS
C21: To Do | D21: In Progress | E21: Done | F21: Blocked
B22: NOTE ON PACE (important)
B23: Dates are TARGETS Nikhil owns — not deadlines. Sprints flex. Depth & correctness always beat speed; if a topic needs more time, the plan bends, the topic never gets skimmed.
B24: Biggest single rock: Python / FastAPI / Pydantic (~100–130 hrs, spread across Sprints 1–2).
B25: Biggest ROI differentiator: the LLMOps / Eval bucket (golden dataset + LLM-as-Judge) — this is what pushes pay into the ₹20L+ band.

Sheet Sprint Board
A1: ID | B1: Sprint | C1: Stream / Epic | D1: Task | E1: Sub-topics | F1: Priority | G1: Est Hrs | H1: Status | I1: Date Done | J1: Notes
A2: 1-01 | B2: Sprint 1 | C2: Foundations | D2: Embeddings (finish) | E2: vectors, cosine vs euclidean, ANN/HNSW, vendor dedup | F2: P0 | G2: 8 | H2: To Do | J2: In progress now
A3: 1-02 | B3: Sprint 1 | C3: Foundations | D3: Inference & sampling | E3: temperature, top-p, top-k, greedy decoding | F3: P0 | G3: 6 | H3: To Do | J3: temp=0 for invoice extraction
A4: 1-03 | B4: Sprint 1 | C4: Foundations | D4: Context window | E4: token budget, sliding window, summarization | F4: P0 | G4: 6 | H4: To Do
A5: 1-04 | B5: Sprint 1 | C5: Foundations | D5: Hallucinations | E5: causes, detection, grounding | F5: P0 | G5: 6 | H5: To Do
A6: 1-05 | B6: Sprint 1 | C6: Courses | D6: Anthropic: API Fundamentals | E6: messages format, models, params | F6: P0 | G6: 4 | H6: To Do | J6: Colab
A7: 1-06 | B7: Sprint 1 | C7: Courses | D7: Anthropic: Prompt Engineering (9 ch) | E7: few-shot, chain-of-thought, system prompts | F7: P0 | G7: 12 | H7: To Do | J7: Colab
A8: 1-07 | B8: Sprint 1 | C8: Python | D8: Python basics (start) | E8: syntax vs JS, types, f-strings, control flow | F8: P0 | G8: 16 | H8: To Do | J8: Biggest rock — spreads into S2
A9: 1-08 | B9: Sprint 1 | C9: Setup | D9: FinOps repo + Supabase | E9: scaffold, env, Postgres + pgvector setup | F9: P0 | G9: 6 | H9: To Do
A10: 1-09 | B10: Sprint 1 | C10: Foundations | D10: Recall + Bolo locks | E10: blank-recall, spoken explain, capsule lock | F10: P0 | G10: 6 | H10: To Do | J10: Forge — interview defense
A11: 2-10 | B11: Sprint 2 | C11: Python | D11: Python basics (finish) | E11: modules, error handling, file/JSON | F11: P0 | G11: 12 | H11: To Do
A12: 2-11 | B12: Sprint 2 | C12: Python | D12: FastAPI | E12: routes, async endpoints, request/response | F12: P0 | G12: 10 | H12: To Do | J12: AI backend = Python
A13: 2-12 | B13: Sprint 2 | C13: Python | D13: Pydantic | E13: force LLM -> strict typed output | F13: P0 | G13: 8 | H13: To Do | J13: Core tool for reliable extraction
A14: 2-13 | B14: Sprint 2 | C14: Courses | D14: Anthropic: Tool Use | E14: function-calling course | F14: P0 | G14: 6 | H14: To Do | J14: Colab
A15: 2-14 | B15: Sprint 2 | C15: LLM-API | D15: Structured / JSON output + validation | E15: schema-forcing, parse, validate | F15: P0 | G15: 6 | H15: To Do
A16: 2-15 | B16: Sprint 2 | C16: LLM-API | D16: Multimodal / vision input | E16: scanned & image invoice -> text | F16: P0 | G16: 8 | H16: To Do | J16: Extraction core
A17: 2-16 | B17: Sprint 2 | C17: LLM-API | D17: Prompt engineering (hands-on) | E17: extraction prompts, edge cases | F17: P0 | G17: 6 | H17: To Do
A18: 2-17 | B18: Sprint 2 | C18: Domain | D18: Compliance: TDS/TCS/DTAA (start) | E18: 194C/194J/194H, TCS 206C, DTAA treaties | F18: P0 | G18: 10 | H18: To Do | J18: Re-learn from zero
A19: 2-18 | B19: Sprint 2 | C19: Cross-cut | D19: 'Where NOT to use AI' | E19: deterministic TDS math in code | F19: P0 | G19: 4 | H19: To Do | J19: Senior signal — defend in interview
A20: 2-19 | B20: Sprint 2 | C20: Build | D20: M1: Upload -> extraction (Postman) | E20: FastAPI endpoint, JSON out, no UI yet | F20: P0 | G20: 14 | H20: To Do | J20: First working slice
A21: 3-20 | B21: Sprint 3 | C21: Domain | D21: Compliance: TDS/TCS/DTAA (finish) | E21: thresholds, individual vs company rate | F21: P0 | G21: 8 | H21: To Do
A22: 3-21 | B22: Sprint 3 | C22: LLMOps | D22: Golden dataset + metrics | E22: 30 real invoices, precision / recall / F1 | F22: P0 | G22: 10 | H22: To Do | J22: Secret weapon
A23: 3-22 | B23: Sprint 3 | C23: LLMOps | D23: LLM-as-Judge | E23: auto-grade extraction vs ground truth | F23: P0 | G23: 8 | H23: To Do
A24: 3-23 | B24: Sprint 3 | C24: Courses | D24: Anthropic: Evaluations | E24: eval design, metrics | F24: P0 | G24: 6 | H24: To Do | J24: Colab
A25: 3-24 | B25: Sprint 3 | C25: LLMOps | D25: Observability | E25: tokens / latency / cost / prompt-version | F25: P0 | G25: 6 | H25: To Do | J25: api_logs table
A26: 3-25 | B26: Sprint 3 | C26: LLM-API | D26: Confidence / trust scoring | E26: 0-100 + action thresholds | F26: P0 | G26: 4 | H26: To Do
A27: 3-26 | B27: Sprint 3 | C27: LLMOps | D27: Guardrails + error handling + caching | E27: input/output validation, DEMO_MODE | F27: P0 | G27: 8 | H27: To Do
A28: 3-27 | B28: Sprint 3 | C28: LLM-API | D28: Multi-model verification | E28: Claude + GPT, agree/disagree | F28: P1 | G28: 8 | H28: To Do
A29: 3-28 | B29: Sprint 3 | C29: Build | D29: M1: Eval Dashboard | E29: accuracy %, tracing, version compare | F29: P0 | G29: 14 | H29: To Do | J29: THE hireable artifact
A30: 4-29 | B30: Sprint 4 | C30: LLM-API | D30: Streaming (SSE) + structured streaming | E30: word-by-word, field-by-field UI | F30: P0 | G30: 8 | H30: To Do
A31: 4-30 | B31: Sprint 4 | C31: LLMOps | D31: Human-in-loop / 'Teach the AI' RLHF | E31: user corrections -> re-evaluate | F31: P0 | G31: 8 | H31: To Do | J31: Anchor principle
A32: 4-31 | B32: Sprint 4 | C32: Full-Stack | D32: React UI + build M1 frontend | E32: refresh React, wire to backend | F32: P0 | G32: 14 | H32: To Do
A33: 4-32 | B33: Sprint 4 | C33: Full-Stack | D33: Vercel deploy | E33: env, prod config, live URL | F33: P0 | G33: 4 | H33: To Do
A34: 4-33 | B34: Sprint 4 | C34: LLMOps | D34: Explainability / reasoning flowchart | E34: 'Show AI Details' 3-level toggle | F34: P1 | G34: 6 | H34: To Do
A35: 4-34 | B35: Sprint 4 | C35: Career | D35: Resume + positioning narrative | E35: ex-FinOps -> AI Product framing | F35: P0 | G35: 8 | H35: To Do
A36: 4-35 | B36: Sprint 4 | C36: Career | D36: LinkedIn + Loom demo video | E36: profile rewrite + M1 walkthrough | F36: P0 | G36: 8 | H36: To Do
A37: 4-36 | B37: Sprint 4 | C37: Career | D37: 🚩 APPLICATIONS BEGIN | E37: fintech-AI + applied-AI roles | F37: P0 | G37: 6 | H37: To Do | J37: Trigger: M1 demo-able
A38: 4-37 | B38: Sprint 4 | C38: Career | D38: Interview prep: concept Q&A (start) | E38: drill bucket concepts cold | F38: P0 | G38: 6 | H38: To Do
A39: 5-38 | B39: Sprint 5 | C39: RAG | D39: Vector search | E39: pgvector + FAISS | F39: P0 | G39: 10 | H39: To Do
A40: 5-39 | B40: Sprint 5 | C40: RAG | D40: Chunking | E40: semantic / section-aware | F40: P0 | G40: 6 | H40: To Do
...

Sheet Sprint Plan
A1: Sprint | B1: Dates (2 wks, Sun off) | C1: Theme | D1: Key Deliverable / Demo at sprint-end | E1: Apply?
A2: Sprint 1 | B2: 22 Jun – 04 Jul | C2: Foundations + Setup | D2: 5 foundation concepts locked; Prompt-Eng course done; first Claude API call; FinOps repo + Supabase live. | E2: Not yet
A3: Sprint 2 | B3: 06 Jul – 18 Jul | C3: M1 Extraction Core (Python) | D3: Upload invoice -> structured JSON via FastAPI/Pydantic (Postman). TDS math in deterministic code. | E3: Not yet
A4: Sprint 3 | B4: 20 Jul – 01 Aug | C4: M1 Trust + Eval Engine | D4: Eval Dashboard: '94% precision on 30 invoices' + tracing + version compare. ← hireable proof. | E4: Not yet
A5: Sprint 4 | B5: 03 Aug – 15 Aug | C5: M1 Full-Stack + SHIP | D5: M1 LIVE on Vercel: slick UI, streaming, human-in-loop, eval-backed. Resume + Loom video out. | E5: 🚩 START
A6: Sprint 5 | B6: 17 Aug – 29 Aug | C6: RAG + M2 Bank Recon | D6: RAG over past invoices; M2 reconciliation working; Dockerised local. Interviewing in parallel. | E6: Ongoing
A7: Sprint 6 | B7: 31 Aug – 12 Sep | C7: Agents + Interview Hardening | D7: Agent feature live; full Bucket-1/3/4 coverage; mock-interview ready across all concepts. | E7: Ongoing

Sheet Dashboard
A1: LIVE PROGRESS DASHBOARD
A2: Auto-calculated from Sprint Board. Updates as Nidhi changes Status.
A4: OVERALL (Phase 1)
A5: Total tasks | B5: =COUNTA('Sprint Board'!$B$2:$B$56) -> 55
A6: Done | B6: =COUNTIF('Sprint Board'!$H$2:$H$56,"Done") -> 0
A7: In Progress | B7: =COUNTIF('Sprint Board'!$H$2:$H$56,"In Progress") -> 0
A8: Blocked | B8: =COUNTIF('Sprint Board'!$H$2:$H$56,"Blocked") -> 0
A9: % Complete | B9: =COUNTIF('Sprint Board'!$H$2:$H$56,"Done")/COUNTA('Sprint Board'!$B$2:$B$56) -> 0
A10: Total est hrs | B10: =SUM('Sprint Board'!$G$2:$G$56) -> 438
A11: Hrs done | B11: =SUMIF('Sprint Board'!$H$2:$H$56,"Done",'Sprint Board'!$G$2:$G$56) -> 0
A13: BY SPRINT
A14: Sprint | B14: Tasks | C14: Done | D14: % Complete | E14: Progress | F14: Est Hrs | G14: Hrs Done
A15: Sprint 1 | B15: =COUNTIF('Sprint Board'!$B$2:$B$56,"Sprint 1") -> 9 | C15: =COUNTIFS('Sprint Board'!$B$2:$B$56,"Sprint 1",'Sprint Board'!$H$2:$H$56,"Done") -> 0 | D15: =IFERROR(COUNTIFS('Sprint Board'!$B$2:$B$56,"Sprint 1",'Sprint Board'!$H$2:$H$56,"Done")/COUNTIF('Sprint Board'!$B$2:$B$56,"Sprint 1"),0) -> 0 | E15: =REPT("|",ROUND(D15*20,0))&REPT(".",20-ROUND(D15*20,0)) -> .................... | F15: =SUMIF('Sprint Board'!$B$2:$B$56,"Sprint 1",'Sprint Board'!$G$2:$G$56) -> 70 | G15: =SUMIFS('Sprint Board'!$G$2:$G$56,'Sprint Board'!$B$2:$B$56,"Sprint 1",'Sprint Board'!$H$2:$H$56,"Done") -> 0
A16: Sprint 2 | B16: =COUNTIF('Sprint Board'!$B$2:$B$56,"Sprint 2") -> 10 | C16: =COUNTIFS('Sprint Board'!$B$2:$B$56,"Sprint 2",'Sprint Board'!$H$2:$H$56,"Done") -> 0 | D16: =IFERROR(COUNTIFS('Sprint Board'!$B$2:$B$56,"Sprint 2",'Sprint Board'!$H$2:$H$56,"Done")/COUNTIF('Sprint Board'!$B$2:$B$56,"Sprint 2"),0) -> 0 | E16: =REPT("|",ROUND(D16*20,0))&REPT(".",20-ROUND(D16*20,0)) -> .................... | F16: =SUMIF('Sprint Board'!$B$2:$B$56,"Sprint 2",'Sprint Board'!$G$2:$G$56) -> 84 | G16: =SUMIFS('Sprint Board'!$G$2:$G$56,'Sprint Board'!$B$2:$B$56,"Sprint 2",'Sprint Board'!$H$2:$H$56,"Done") -> 0
A17: Sprint 3 | B17: =COUNTIF('Sprint Board'!$B$2:$B$56,"Sprint 3") -> 9 | C17: =COUNTIFS('Sprint Board'!$B$2:$B$56,"Sprint 3",'Sprint Board'!$H$2:$H$56,"Done") -> 0 | D17: =IFERROR(COUNTIFS('Sprint Board'!$B$2:$B$56,"Sprint 3",'Sprint Board'!$H$2:$H$56,"Done")/COUNTIF('Sprint Board'!$B$2:$B$56,"Sprint 3"),0) -> 0 | E17: =REPT("|",ROUND(D17*20,0))&REPT(".",20-ROUND(D17*20,0)) -> .................... | F17: =SUMIF('Sprint Board'!$B$2:$B$56,"Sprint 3",'Sprint Board'!$G$2:$G$56) -> 72 | G17: =SUMIFS('Sprint Board'!$G$2:$G$56,'Sprint Board'!$B$2:$B$56,"Sprint 3",'Sprint Board'!$H$2:$H$56,"Done") -> 0
A18: Sprint 4 | B18: =COUNTIF('Sprint Board'!$B$2:$B$56,"Sprint 4") -> 9 | C18: =COUNTIFS('Sprint Board'!$B$2:$B$56,"Sprint 4",'Sprint Board'!$H$2:$H$56,"Done") -> 0 | D18: =IFERROR(COUNTIFS('Sprint Board'!$B$2:$B$56,"Sprint 4",'Sprint Board'!$H$2:$H$56,"Done")/COUNTIF('Sprint Board'!$B$2:$B$56,"Sprint 4"),0) -> 0 | E18: =REPT("|",ROUND(D18*20,0))&REPT(".",20-ROUND(D18*20,0)) -> .................... | F18: =SUMIF('Sprint Board'!$B$2:$B$56,"Sprint 4",'Sprint Board'!$G$2:$G$56) -> 68 | G18: =SUMIFS('Sprint Board'!$G$2:$G$56,'Sprint Board'!$B$2:$B$56,"Sprint 4",'Sprint Board'!$H$2:$H$56,"Done") -> 0
A19: Sprint 5 | B19: =COUNTIF('Sprint Board'!$B$2:$B$56,"Sprint 5") -> 9 | C19: =COUNTIFS('Sprint Board'!$B$2:$B$56,"Sprint 5",'Sprint Board'!$H$2:$H$56,"Done") -> 0 | D19: =IFERROR(COUNTIFS('Sprint Board'!$B$2:$B$56,"Sprint 5",'Sprint Board'!$H$2:$H$56,"Done")/COUNTIF('Sprint Board'!$B$2:$B$56,"Sprint 5"),0) -> 0 | E19: =REPT("|",ROUND(D19*20,0))&REPT(".",20-ROUND(D19*20,0)) -> .................... | F19: =SUMIF('Sprint Board'!$B$2:$B$56,"Sprint 5",'Sprint Board'!$G$2:$G$56) -> 72 | G19: =SUMIFS('Sprint Board'!$G$2:$G$56,'Sprint Board'!$B$2:$B$56,"Sprint 5",'Sprint Board'!$H$2:$H$56,"Done") -> 0
A20: Sprint 6 | B20: =COUNTIF('Sprint Board'!$B$2:$B$56,"Sprint 6") -> 9 | C20: =COUNTIFS('Sprint Board'!$B$2:$B$56,"Sprint 6",'Sprint Board'!$H$2:$H$56,"Done") -> 0 | D20: =IFERROR(COUNTIFS('Sprint Board'!$B$2:$B$56,"Sprint 6",'Sprint Board'!$H$2:$H$56,"Done")/COUNTIF('Sprint Board'!$B$2:$B$56,"Sprint 6"),0) -> 0 | E20: =REPT("|",ROUND(D20*20,0))&REPT(".",20-ROUND(D20*20,0)) -> .................... | F20: =SUMIF('Sprint Board'!$B$2:$B$56,"Sprint 6",'Sprint Board'!$G$2:$G$56) -> 72 | G20: =SUMIFS('Sprint Board'!$G$2:$G$56,'Sprint Board'!$B$2:$B$56,"Sprint 6",'Sprint Board'!$H$2:$H$56,"Done") -> 0
A21: TOTAL | B21: =SUM(B15:B20) -> 55 | C21: =SUM(C15:C20) -> 0 | D21: =IFERROR(C21/B21,0) -> 0 | F21: =SUM(F15:F20) -> 438 | G21: =SUM(G15:G20) -> 0

Sheet Phase 2 Backlog
A1: PHASE 2 — BETTER COMPANIES / GROWTH (after job, or in parallel — no fixed dates)
A2: Item | B2: Sub-topics | C2: Priority | D2: Est Time | E2: Status
A3: Build: M3 Procurement | B3: optimization, constraint-satisfaction, LP solver, multi-objective scoring, what-if | C3: P2 | D3: 1–2 wk | E3: To Do
A4: Graph RAG | B4: NetworkX, vendor-fraud-network detection | C4: P2 | D4: 3–4 d | E4: To Do
A5: LlamaIndex | B5: framework RAG vs from-scratch | C5: P2 | D5: 3 d | E5: To Do
A6: Multi-agent + MCP server | B6: agent collaboration, build MCP tools | C6: P2 | D6: 1 wk | E6: To Do
A7: Agent memory | B7: episodic / semantic / procedural | C7: P2 | D7: 2–3 d | E7: To Do
A8: Cloud / MLOps (deep) | B8: Docker deep, Kubernetes, AWS/GCP — gates highest pay | C8: P2 | D8: 4–6 wk | E8: To Do
A9: LangChain + LangSmith / Phoenix | B9: orchestration + agent tracing / token-cost | C9: P2 | D9: 1 wk | E9: To Do
A10: Fine-tuning / LoRA-QLoRA | B10: when vs prompt, PEFT, data prep | C10: P2 | D10: 1 wk | E10: To Do
A11: Quantization + Ollama | B11: local LLMs, 4/8-bit | C11: P2 | D11: 1 wk | E11: To Do
A12: System design (deep) | B12: LLM-app architecture, scale, failure | C12: P2 | D12: 1 wk | E12: To Do
A13: TypeScript migration | B13: if not done in Phase 1 | C13: P2 | D13: 3–4 d | E13: To Do
... A16: Discuss-fluently set | B16: distillation, MoE, Constitutional AI, RLHF vs DPO | C16: P2 | D16: 3–4 d | E16: To Do
